[2023-11-27T07:23:58.040+0000] {taskinstance.py:1171} INFO - Dependencies all met for <TaskInstance: fetch_clean_elastic.connect manual__2023-11-27T07:23:56.916472+00:00 [queued]>
[2023-11-27T07:23:58.045+0000] {taskinstance.py:1171} INFO - Dependencies all met for <TaskInstance: fetch_clean_elastic.connect manual__2023-11-27T07:23:56.916472+00:00 [queued]>
[2023-11-27T07:23:58.046+0000] {taskinstance.py:1368} INFO - 
--------------------------------------------------------------------------------
[2023-11-27T07:23:58.046+0000] {taskinstance.py:1369} INFO - Starting attempt 1 of 2
[2023-11-27T07:23:58.046+0000] {taskinstance.py:1370} INFO - 
--------------------------------------------------------------------------------
[2023-11-27T07:23:58.055+0000] {taskinstance.py:1389} INFO - Executing <Task(PythonOperator): connect> on 2023-11-27 07:23:56.916472+00:00
[2023-11-27T07:23:58.061+0000] {standard_task_runner.py:52} INFO - Started process 263 to run task
[2023-11-27T07:23:58.063+0000] {standard_task_runner.py:79} INFO - Running: ['***', 'tasks', 'run', 'fetch_clean_elastic', 'connect', 'manual__2023-11-27T07:23:56.916472+00:00', '--job-id', '2', '--raw', '--subdir', 'DAGS_FOLDER/P2M3_Sifra_Siregar_DAG.py', '--cfg-path', '/tmp/tmpg0s__k8a', '--error-file', '/tmp/tmpz7z_ghi3']
[2023-11-27T07:23:58.064+0000] {standard_task_runner.py:80} INFO - Job 2: Subtask connect
[2023-11-27T07:23:58.105+0000] {task_command.py:371} INFO - Running <TaskInstance: fetch_clean_elastic.connect manual__2023-11-27T07:23:56.916472+00:00 [running]> on host bc2751e23436
[2023-11-27T07:23:58.143+0000] {taskinstance.py:1583} INFO - Exporting the following env vars:
AIRFLOW_CTX_DAG_OWNER=sifra
AIRFLOW_CTX_DAG_ID=fetch_clean_elastic
AIRFLOW_CTX_TASK_ID=connect
AIRFLOW_CTX_EXECUTION_DATE=2023-11-27T07:23:56.916472+00:00
AIRFLOW_CTX_TRY_NUMBER=1
AIRFLOW_CTX_DAG_RUN_ID=manual__2023-11-27T07:23:56.916472+00:00
[2023-11-27T07:23:58.146+0000] {taskinstance.py:1902} ERROR - Task failed with exception
Traceback (most recent call last):
  File "/home/airflow/.local/lib/python3.7/site-packages/pandas/io/sql.py", line 2056, in execute
    cur.execute(*args, **kwargs)
psycopg2.errors.UndefinedTable: relation "table_m3" does not exist
LINE 1: SELECT * FROM table_m3
                      ^


The above exception was the direct cause of the following exception:

Traceback (most recent call last):
  File "/home/airflow/.local/lib/python3.7/site-packages/airflow/operators/python.py", line 171, in execute
    return_value = self.execute_callable()
  File "/home/airflow/.local/lib/python3.7/site-packages/airflow/operators/python.py", line 189, in execute_callable
    return self.python_callable(*self.op_args, **self.op_kwargs)
  File "/opt/airflow/dags/P2M3_Sifra_Siregar_DAG.py", line 48, in getdata
    data = pd.read_sql ('SELECT * FROM table_m3', conn)
  File "/home/airflow/.local/lib/python3.7/site-packages/pandas/io/sql.py", line 608, in read_sql
    chunksize=chunksize,
  File "/home/airflow/.local/lib/python3.7/site-packages/pandas/io/sql.py", line 2116, in read_query
    cursor = self.execute(*args)
  File "/home/airflow/.local/lib/python3.7/site-packages/pandas/io/sql.py", line 2068, in execute
    raise ex from exc
pandas.io.sql.DatabaseError: Execution failed on sql 'SELECT * FROM table_m3': relation "table_m3" does not exist
LINE 1: SELECT * FROM table_m3
                      ^

[2023-11-27T07:23:58.153+0000] {taskinstance.py:1412} INFO - Marking task as UP_FOR_RETRY. dag_id=fetch_clean_elastic, task_id=connect, execution_date=20231127T072356, start_date=20231127T072358, end_date=20231127T072358
[2023-11-27T07:23:58.165+0000] {standard_task_runner.py:97} ERROR - Failed to execute job 2 for task connect (Execution failed on sql 'SELECT * FROM table_m3': relation "table_m3" does not exist
LINE 1: SELECT * FROM table_m3
                      ^
; 263)
[2023-11-27T07:23:58.197+0000] {local_task_job.py:156} INFO - Task exited with return code 1
[2023-11-27T07:23:58.220+0000] {local_task_job.py:279} INFO - 0 downstream tasks scheduled from follow-on schedule check
